
#######################################################################
# +-----------------------------------------------------------------+ #
# |                            BO3 object                           | #
# +-----------------------------------------------------------------+ #
#######################################################################

Author: LordSmellyPants

Description: No description given

Version: 3

SettingsMode: WriteWithoutComments


#######################################################################
# +-----------------------------------------------------------------+ #
# |                          Main settings                          | #
# +-----------------------------------------------------------------+ #
#######################################################################

Tree: true

Frequency: 1

Rarity: 10.0

RotateRandomly: true

SpawnHeight: highestSolidBlock

SpawnHeightOffset: 0

SpawnHeightVariance: 0

##############################
# Height Limits for the BO3. #
##############################

MinHeight: 62

MaxHeight: 255

######################
# Extrusion settings #
######################

ExtrudeMode: None

ExtrudeThroughBlocks: AIR

MaxBranchDepth: 10

ExcludedBiomes: All


#######################################################################
# +-----------------------------------------------------------------+ #
# |                      Source block settings                      | #
# +-----------------------------------------------------------------+ #
#######################################################################

SourceBlocks: STONE:1,STONE:3,STONE:5,DIRT:1,DIRT,SAND,GRASS,DIRT:2,STATIONARY_WATER,HARD_CLAY,STAINED_CLAY,CLAY,SANDSTONE,SAND:1,AIR,STONE,GRAVEL,LONG_GRASS,LONG_GRASS:1,LONG_GRASS:2,DEAD_BUSH,YELLOW_FLOWER,RED_ROSE,BROWN_MUSHROOM,RED_MUSHROOM,biomesoplenty:plant_0:1,biomesoplenty:plant_0:2,biomesoplenty:plant_0:3,biomesoplenty:plant_0:4,biomesoplenty:plant_0:5,biomesoplenty:plant_0:6,biomesoplenty:plant_0:7,biomesoplenty:plant_0:8,biomesoplenty:plant_0:9,biomesoplenty:plant_0:10,biomesoplenty:plant_0:11,biomesoplenty:plant_0:12,biomesoplenty:plant_0:13,biomesoplenty:plant_0:14,biomesoplenty:flower_0:1,biomesoplenty:flower_0:2,biomesoplenty:flower_0:3,biomesoplenty:flower_0:4,biomesoplenty:flower_0:5,biomesoplenty:flower_0:6,biomesoplenty:flower_0:7,biomesoplenty:flower_0:8,biomesoplenty:flower_0:9,biomesoplenty:flower_0:10,biomesoplenty:flower_0:11,biomesoplenty:flower_0:12,biomesoplenty:flower_0:13,biomesoplenty:flower_0:14,biomesoplenty:plant_1,biomesoplenty:grass:0,biomesoplenty:grass:1,biomesoplenty:grass,biomesoplenty:grass:3,biomesoplenty:grass:4,biomesoplenty:grass:5,biomesoplenty:grass:6,biomesoplenty:grass:7,UNKNOWN_BLOCK:0,UNKNOWN_BLOCK:1,UNKNOWN_BLOCK:2,UNKNOWN_BLOCK:8,UNKNOWN_BLOCK:9,UNKNOWN_BLOCK:10,biomesoplenty:dried_sand,biomesoplenty:hard_ice,biomesoplenty:white_sand,biomesoplenty:white_sandstone,biomesoplenty:mud,biomesoplenty:ash_block

MaxPercentageOutsideSourceBlock: 0

OutsideSourceBlock: placeAnyway

DoReplaceBlocks: true

IsOTGPlus: false


#######################################################################
# +-----------------------------------------------------------------+ #
# |                              Blocks                             | #
# +-----------------------------------------------------------------+ #
#######################################################################

Block(-9,16,-4,LEAVES)
Block(-9,17,-5,LEAVES)
Block(-9,17,-4,LEAVES)
Block(-9,17,-3,LEAVES)
Block(-9,18,-4,LEAVES)
Block(-8,16,-6,LEAVES)
Block(-8,16,-5,LEAVES)
Block(-8,16,-4,LEAVES)
Block(-8,16,-3,LEAVES)
Block(-8,17,-6,LEAVES)
Block(-8,17,-5,LEAVES)
Block(-8,17,-4,LEAVES)
Block(-8,17,-3,LEAVES)
Block(-8,17,-2,LEAVES)
Block(-8,18,-5,LEAVES)
Block(-8,18,-4,LEAVES)
Block(-8,18,-3,LEAVES)
Block(-8,19,-4,LEAVES)
Block(-7,16,-6,LEAVES)
Block(-7,16,-5,LEAVES)
Block(-7,16,-4,LEAVES)
Block(-7,17,-7,LEAVES)
Block(-7,17,-6,LEAVES)
Block(-7,17,-5,LEAVES)
Block(-7,17,-4,LEAVES)
Block(-7,17,-3,LEAVES)
Block(-7,17,-2,LEAVES)
Block(-7,17,-1,LEAVES)
Block(-7,18,-6,LEAVES)
Block(-7,18,-5,LEAVES)
Block(-7,18,-4,LEAVES)
Block(-7,18,-3,LEAVES)
Block(-7,18,-2,LEAVES)
Block(-7,18,1,LEAVES)
Block(-7,19,-6,LEAVES)
Block(-7,19,-5,LEAVES)
Block(-7,19,-4,LEAVES)
Block(-7,19,-3,LEAVES)
Block(-7,19,0,LEAVES)
Block(-7,19,1,LEAVES)
Block(-7,19,2,LEAVES)
Block(-7,20,-4,LEAVES)
Block(-7,20,1,LEAVES)
Block(-6,16,-7,LEAVES)
Block(-6,16,-6,LEAVES)
Block(-6,16,-5,LEAVES)
Block(-6,16,-4,LEAVES)
Block(-6,16,-3,LEAVES)
Block(-6,16,-2,LEAVES)
Block(-6,16,-1,LEAVES)
Block(-6,17,-7,LEAVES)
Block(-6,17,-6,LEAVES)
Block(-6,17,-5,LEAVES)
Block(-6,17,-4,LOG)
Block(-6,17,-3,LEAVES)
Block(-6,17,-2,LEAVES)
Block(-6,17,-1,LEAVES)
Block(-6,18,-7,LEAVES)
Block(-6,18,-6,LEAVES)
Block(-6,18,-5,LEAVES)
Block(-6,18,-4,LEAVES)
Block(-6,18,-3,LEAVES)
Block(-6,18,-2,LEAVES)
Block(-6,18,-1,LEAVES)
Block(-6,18,0,LEAVES)
Block(-6,18,1,LEAVES)
Block(-6,19,-6,LEAVES)
Block(-6,19,-5,LEAVES)
Block(-6,19,-4,LEAVES)
Block(-6,19,-3,LEAVES)
Block(-6,19,-2,LEAVES)
Block(-6,19,-1,LEAVES)
Block(-6,19,0,LEAVES)
Block(-6,19,1,LEAVES)
Block(-6,19,2,LEAVES)
Block(-6,19,3,LEAVES)
Block(-6,20,-5,LEAVES)
Block(-6,20,-4,LEAVES)
Block(-6,20,-3,LEAVES)
Block(-6,20,0,LEAVES)
Block(-6,20,1,LEAVES)
Block(-6,20,2,LEAVES)
Block(-6,21,1,LEAVES)
Block(-5,15,-6,LEAVES)
Block(-5,15,-5,LEAVES)
Block(-5,15,-4,LEAVES)
Block(-5,16,-6,LEAVES)
Block(-5,16,-5,LOG:8)
Block(-5,16,-4,LOG:8)
Block(-5,16,-3,LOG:4)
Block(-5,17,-7,LEAVES)
Block(-5,17,-6,LEAVES)
Block(-5,17,-5,LEAVES)
Block(-5,17,-4,LEAVES)
Block(-5,17,-3,LEAVES)
Block(-5,17,-2,LEAVES)
Block(-5,17,-1,LEAVES)
Block(-5,18,-6,LEAVES)
Block(-5,18,-5,LEAVES)
Block(-5,18,-4,LEAVES)
Block(-5,18,-3,LEAVES)
Block(-5,18,-2,LEAVES)
Block(-5,18,-1,LEAVES)
Block(-5,18,0,LEAVES)
Block(-5,18,1,LEAVES)
Block(-5,18,2,LEAVES)
Block(-5,18,3,LEAVES)
Block(-5,19,-6,LEAVES)
Block(-5,19,-5,LEAVES)
Block(-5,19,-4,LEAVES)
Block(-5,19,-3,LEAVES)
Block(-5,19,-2,LEAVES)
Block(-5,19,-1,LEAVES)
Block(-5,19,0,LEAVES)
Block(-5,19,1,LOG)
Block(-5,19,2,LEAVES)
Block(-5,19,3,LEAVES)
Block(-5,20,-4,LEAVES)
Block(-5,20,-1,LEAVES)
Block(-5,20,0,LEAVES)
Block(-5,20,1,LEAVES)
Block(-5,20,2,LEAVES)
Block(-5,20,3,LEAVES)
Block(-5,21,0,LEAVES)
Block(-5,21,1,LEAVES)
Block(-5,21,2,LEAVES)
Block(-4,15,-5,LEAVES)
Block(-4,15,-3,LOG:4)
Block(-4,16,-6,LEAVES)
Block(-4,16,-5,LEAVES)
Block(-4,16,-4,LEAVES)
Block(-4,16,-3,LOG:4)
Block(-4,17,-6,LEAVES)
Block(-4,17,-5,LEAVES)
Block(-4,17,-4,LEAVES)
Block(-4,17,-3,LEAVES)
Block(-4,17,-2,LEAVES)
Block(-4,18,-6,LEAVES)
Block(-4,18,-5,LEAVES)
Block(-4,18,-4,LEAVES)
Block(-4,18,-3,LEAVES)
Block(-4,18,-2,LEAVES)
Block(-4,18,1,LOG:4)
Block(-4,18,2,LEAVES)
Block(-4,19,-5,LEAVES)
Block(-4,19,-4,LEAVES)
Block(-4,19,-3,LEAVES)
Block(-4,19,-1,LEAVES)
Block(-4,19,0,LEAVES)
Block(-4,19,1,LEAVES)
Block(-4,19,2,LEAVES)
Block(-4,19,3,LEAVES)
Block(-4,20,0,LEAVES)
Block(-4,20,1,LEAVES)
Block(-4,20,2,LEAVES)
Block(-4,21,1,LEAVES)
Block(-3,15,-3,LOG:4)
Block(-3,15,-2,LOG:4)
Block(-3,16,-4,LEAVES)
Block(-3,17,-5,LEAVES)
Block(-3,17,-4,LEAVES)
Block(-3,17,-3,LEAVES)
Block(-3,18,-4,LEAVES)
Block(-3,18,1,LOG:4)
Block(-3,19,-4,LEAVES)
Block(-3,19,0,LEAVES)
Block(-3,19,1,LEAVES)
Block(-3,19,2,LEAVES)
Block(-3,20,-5,LEAVES)
Block(-3,20,-4,LEAVES)
Block(-3,20,-3,LEAVES)
Block(-3,20,-2,LEAVES)
Block(-3,20,1,LEAVES)
Block(-3,21,-4,LEAVES)
Block(-3,22,0,LEAVES)
Block(-3,23,-1,LEAVES)
Block(-3,23,0,LEAVES)
Block(-3,23,1,LEAVES)
Block(-3,24,0,LEAVES)
Block(-3,25,0,LEAVES)
Block(-3,26,-1,LEAVES)
Block(-3,26,0,LEAVES)
Block(-3,26,1,LEAVES)
Block(-3,27,0,LEAVES)
Block(-2,15,-1,LOG:4)
Block(-2,18,0,LOG:4)
Block(-2,19,-5,LEAVES)
Block(-2,19,-4,LEAVES)
Block(-2,20,-6,LEAVES)
Block(-2,20,-5,LEAVES)
Block(-2,20,-4,LEAVES)
Block(-2,20,-2,LOG:4)
Block(-2,20,-1,LEAVES)
Block(-2,20,3,LEAVES)
Block(-2,21,-5,LEAVES)
Block(-2,21,-4,LEAVES)
Block(-2,21,-3,LEAVES)
Block(-2,21,2,LEAVES)
Block(-2,21,3,LEAVES)
Block(-2,21,4,LEAVES)
Block(-2,22,-4,LEAVES)
Block(-2,22,-1,LEAVES)
Block(-2,22,0,LEAVES)
Block(-2,22,1,LEAVES)
Block(-2,22,3,LEAVES)
Block(-2,23,-1,LEAVES)
Block(-2,23,0,LOG)
Block(-2,23,1,LEAVES)
Block(-2,24,-1,LEAVES)
Block(-2,24,0,LEAVES)
Block(-2,24,1,LEAVES)
Block(-2,25,-2,LEAVES)
Block(-2,25,0,LEAVES)
Block(-2,25,1,LEAVES)
Block(-2,25,2,LEAVES)
Block(-2,26,-2,LEAVES)
Block(-2,26,-1,LEAVES)
Block(-2,26,0,LEAVES)
Block(-2,26,1,LEAVES)
Block(-2,26,2,LEAVES)
Block(-2,27,-2,LEAVES)
Block(-2,27,-1,LEAVES)
Block(-2,27,0,LEAVES)
Block(-2,27,1,LEAVES)
Block(-2,28,0,LEAVES)
Block(-2,28,1,LEAVES)
Block(-1,15,-1,LOG:4)
Block(-1,18,0,LOG:4)
Block(-1,19,-5,LEAVES)
Block(-1,19,-4,LEAVES)
Block(-1,19,-3,LEAVES)
Block(-1,19,-2,LEAVES)
Block(-1,20,-6,LEAVES)
Block(-1,20,-5,LEAVES)
Block(-1,20,-4,LOG:8)
Block(-1,20,-3,LOG:8)
Block(-1,20,-2,LOG:4)
Block(-1,20,2,LEAVES)
Block(-1,20,3,LEAVES)
Block(-1,20,4,LEAVES)
Block(-1,21,-6,LEAVES)
Block(-1,21,-5,LEAVES)
Block(-1,21,-4,LEAVES)
Block(-1,21,-3,LEAVES)
Block(-1,21,-2,LEAVES)
Block(-1,21,2,LEAVES)
Block(-1,21,3,LOG)
Block(-1,21,4,LEAVES)
Block(-1,22,-5,LEAVES)
Block(-1,22,-4,LEAVES)
Block(-1,22,-3,LEAVES)
Block(-1,22,0,LEAVES)
Block(-1,22,2,LEAVES)
Block(-1,22,3,LEAVES)
Block(-1,22,4,LEAVES)
Block(-1,23,-1,LEAVES)
Block(-1,23,0,LOG)
Block(-1,23,1,LEAVES)
Block(-1,24,0,LEAVES)
Block(-1,25,0,LEAVES)
Block(-1,25,1,LEAVES)
Block(-1,26,-3,LEAVES)
Block(-1,26,-2,LEAVES)
Block(-1,26,-1,LEAVES)
Block(-1,26,0,LEAVES)
Block(-1,26,1,LEAVES)
Block(-1,26,2,LEAVES)
Block(-1,26,3,LEAVES)
Block(-1,27,-2,LEAVES)
Block(-1,27,-1,LEAVES)
Block(-1,27,0,LEAVES)
Block(-1,27,1,LEAVES)
Block(-1,27,2,LEAVES)
Block(-1,28,-2,LEAVES)
Block(-1,28,-1,LEAVES)
Block(-1,28,0,LEAVES)
Block(-1,28,1,LEAVES)
Block(-1,29,0,LEAVES)
Block(0,-1,0,LOG)
Block(0,0,0,LOG)
Block(0,1,0,LOG)
Block(0,2,0,LOG)
Block(0,3,0,LOG)
Block(0,4,0,LOG)
Block(0,5,0,LOG)
Block(0,6,0,LOG)
Block(0,7,0,LOG)
Block(0,8,0,LOG)
Block(0,9,0,LOG)
Block(0,10,0,LOG)
Block(0,11,0,LOG)
Block(0,12,0,LOG)
Block(0,13,0,LOG)
Block(0,14,0,LOG)
Block(0,15,0,LOG)
Block(0,16,0,LOG)
Block(0,17,-5,LEAVES)
Block(0,17,-1,LOG:8)
Block(0,17,0,LOG)
Block(0,18,-6,LEAVES)
Block(0,18,-5,LEAVES)
Block(0,18,-4,LEAVES)
Block(0,18,0,LOG)
Block(0,19,-5,LEAVES)
Block(0,19,-4,LEAVES)
Block(0,19,-3,LEAVES)
Block(0,19,0,LOG)
Block(0,20,-6,LEAVES)
Block(0,20,-5,LEAVES)
Block(0,20,-4,LEAVES)
Block(0,20,-3,LEAVES)
Block(0,20,-2,LEAVES)
Block(0,20,-1,LOG:8)
Block(0,20,0,LOG)
Block(0,20,3,LEAVES)
Block(0,21,-5,LEAVES)
Block(0,21,-4,LEAVES)
Block(0,21,-3,LEAVES)
Block(0,21,0,LOG)
Block(0,21,1,LOG:8)
Block(0,21,2,LOG:8)
Block(0,21,3,LEAVES)
Block(0,21,4,LEAVES)
Block(0,22,-4,LEAVES)
Block(0,22,0,LOG)
Block(0,22,3,LEAVES)
Block(0,23,0,LOG)
Block(0,23,1,LEAVES)
Block(0,24,0,LOG)
Block(0,24,1,LEAVES)
Block(0,24,2,LEAVES)
Block(0,25,-3,LEAVES)
Block(0,25,-2,LEAVES)
Block(0,25,-1,LEAVES)
Block(0,25,0,LOG)
Block(0,25,1,LEAVES)
Block(0,25,2,LEAVES)
Block(0,25,3,LEAVES)
Block(0,26,-3,LEAVES)
Block(0,26,-2,LEAVES)
Block(0,26,-1,LEAVES)
Block(0,26,0,LOG)
Block(0,26,1,LEAVES)
Block(0,26,2,LEAVES)
Block(0,26,3,LEAVES)
Block(0,27,-3,LEAVES)
Block(0,27,-2,LEAVES)
Block(0,27,-1,LEAVES)
Block(0,27,0,LEAVES)
Block(0,27,1,LEAVES)
Block(0,27,2,LEAVES)
Block(0,27,3,LEAVES)
Block(0,28,-2,LEAVES)
Block(0,28,-1,LEAVES)
Block(0,28,0,LEAVES)
Block(0,28,1,LEAVES)
Block(0,28,2,LEAVES)
Block(0,29,-1,LEAVES)
Block(0,29,0,LEAVES)
Block(0,29,1,LEAVES)
Block(1,11,0,LOG:4)
Block(1,14,0,LOG:4)
Block(1,17,-6,LEAVES)
Block(1,17,-5,LEAVES)
Block(1,17,-4,LEAVES)
Block(1,17,-3,LOG:8)
Block(1,17,-2,LOG:8)
Block(1,18,-7,LEAVES)
Block(1,18,-6,LEAVES)
Block(1,18,-5,LEAVES)
Block(1,18,-4,LEAVES)
Block(1,18,-3,LEAVES)
Block(1,19,-7,LEAVES)
Block(1,19,-6,LEAVES)
Block(1,19,-5,LEAVES)
Block(1,19,-4,LEAVES)
Block(1,19,-3,LEAVES)
Block(1,19,0,LOG:4)
Block(1,20,-6,LEAVES)
Block(1,20,-5,LEAVES)
Block(1,20,-4,LEAVES)
Block(1,20,-3,LEAVES)
Block(1,21,-4,LEAVES)
Block(1,21,-1,LEAVES)
Block(1,22,-2,LEAVES)
Block(1,22,-1,LEAVES)
Block(1,22,0,LOG:4)
Block(1,23,-1,LEAVES)
Block(1,23,2,LEAVES)
Block(1,24,0,LEAVES)
Block(1,24,1,LOG:4)
Block(1,24,2,LEAVES)
Block(1,25,-2,LEAVES)
Block(1,25,-1,LEAVES)
Block(1,25,0,LEAVES)
Block(1,25,1,LEAVES)
Block(1,25,2,LEAVES)
Block(1,26,-3,LEAVES)
Block(1,26,-2,LEAVES)
Block(1,26,-1,LEAVES)
Block(1,26,0,LEAVES)
Block(1,26,1,LEAVES)
Block(1,26,2,LEAVES)
Block(1,26,3,LEAVES)
Block(1,27,-2,LEAVES)
Block(1,27,-1,LEAVES)
Block(1,27,0,LEAVES)
Block(1,27,1,LEAVES)
Block(1,27,2,LEAVES)
Block(1,28,-2,LEAVES)
Block(1,28,-1,LEAVES)
Block(1,28,0,LEAVES)
Block(1,28,1,LEAVES)
Block(1,28,2,LEAVES)
Block(1,29,0,LEAVES)
Block(2,11,0,LOG:4)
Block(2,11,1,LOG:4)
Block(2,14,0,LOG:4)
Block(2,17,-6,LEAVES)
Block(2,17,-5,LEAVES)
Block(2,17,-4,LOG:8)
Block(2,18,-8,LEAVES)
Block(2,18,-7,LEAVES)
Block(2,18,-6,LEAVES)
Block(2,18,-5,LOG)
Block(2,18,-4,LEAVES)
Block(2,18,-3,LEAVES)
Block(2,18,-2,LEAVES)
Block(2,19,-7,LEAVES)
Block(2,19,-6,LEAVES)
Block(2,19,-5,LEAVES)
Block(2,19,-4,LEAVES)
Block(2,19,-3,LEAVES)
Block(2,19,1,LOG:4)
Block(2,20,-7,LEAVES)
Block(2,20,-6,LEAVES)
Block(2,20,-5,LEAVES)
Block(2,20,-4,LEAVES)
Block(2,20,-3,LEAVES)
Block(2,21,-5,LEAVES)
Block(2,21,-2,LEAVES)
Block(2,21,-1,LEAVES)
Block(2,21,0,LEAVES)
Block(2,22,-2,LEAVES)
Block(2,22,-1,LOG)
Block(2,22,0,LEAVES)
Block(2,23,-2,LEAVES)
Block(2,23,-1,LEAVES)
Block(2,23,0,LEAVES)
Block(2,23,1,LEAVES)
Block(2,24,0,LEAVES)
Block(2,24,1,LEAVES)
Block(2,24,2,LEAVES)
Block(2,25,-2,LEAVES)
Block(2,25,0,LEAVES)
Block(2,25,1,LEAVES)
Block(2,25,2,LEAVES)
Block(2,26,-2,LEAVES)
Block(2,26,-1,LEAVES)
Block(2,26,0,LEAVES)
Block(2,26,1,LEAVES)
Block(2,26,2,LEAVES)
Block(2,27,-1,LEAVES)
Block(2,27,0,LEAVES)
Block(2,27,1,LEAVES)
Block(2,27,2,LEAVES)
Block(2,28,0,LEAVES)
Block(2,28,1,LEAVES)
Block(3,11,1,LOG:4)
Block(3,12,2,LOG:4)
Block(3,13,4,LEAVES)
Block(3,13,5,LEAVES)
Block(3,14,0,LOG:4)
Block(3,14,4,LEAVES)
Block(3,14,5,LEAVES)
Block(3,17,-7,LEAVES)
Block(3,17,-6,LEAVES)
Block(3,17,-5,LEAVES)
Block(3,17,-4,LEAVES)
Block(3,17,-3,LEAVES)
Block(3,17,-2,LEAVES)
Block(3,18,-8,LEAVES)
Block(3,18,-7,LEAVES)
Block(3,18,-6,LEAVES)
Block(3,18,-5,LOG)
Block(3,18,-4,LEAVES)
Block(3,18,-3,LEAVES)
Block(3,18,-2,LEAVES)
Block(3,19,-8,LEAVES)
Block(3,19,-7,LEAVES)
Block(3,19,-6,LEAVES)
Block(3,19,-5,LEAVES)
Block(3,19,-4,LEAVES)
Block(3,19,-3,LEAVES)
Block(3,19,-2,LEAVES)
Block(3,19,1,LOG:4)
Block(3,19,2,LEAVES)
Block(3,20,-7,LEAVES)
Block(3,20,-6,LEAVES)
Block(3,20,-5,LEAVES)
Block(3,20,-4,LEAVES)
Block(3,20,-3,LEAVES)
Block(3,20,1,LEAVES)
Block(3,20,2,LEAVES)
Block(3,20,3,LEAVES)
Block(3,21,-6,LEAVES)
Block(3,21,-5,LEAVES)
Block(3,21,-4,LEAVES)
Block(3,21,2,LEAVES)
Block(3,22,-2,LEAVES)
Block(3,22,-1,LEAVES)
Block(3,22,0,LEAVES)
Block(3,23,-1,LEAVES)
Block(3,25,0,LEAVES)
Block(3,26,-1,LEAVES)
Block(3,26,0,LEAVES)
Block(3,26,1,LEAVES)
Block(3,27,0,LEAVES)
Block(4,12,2,LOG:4)
Block(4,12,4,LEAVES)
Block(4,12,5,LEAVES)
Block(4,13,4,LEAVES)
Block(4,13,5,LEAVES)
Block(4,13,6,LEAVES)
Block(4,14,0,LOG:4)
Block(4,14,4,LEAVES)
Block(4,14,5,LEAVES)
Block(4,14,6,LEAVES)
Block(4,15,3,LEAVES)
Block(4,15,4,LEAVES)
Block(4,15,5,LEAVES)
Block(4,17,-7,LEAVES)
Block(4,17,-6,LEAVES)
Block(4,17,-5,LEAVES)
Block(4,17,-4,LEAVES)
Block(4,18,-8,LEAVES)
Block(4,18,-7,LEAVES)
Block(4,18,-6,LEAVES)
Block(4,18,-5,LEAVES)
Block(4,18,-4,LEAVES)
Block(4,18,-3,LEAVES)
Block(4,18,-2,LEAVES)
Block(4,19,-7,LEAVES)
Block(4,19,-6,LEAVES)
Block(4,19,-5,LEAVES)
Block(4,19,-4,LEAVES)
Block(4,19,-3,LEAVES)
Block(4,19,1,LEAVES)
Block(4,19,2,LOG:4)
Block(4,20,-6,LEAVES)
Block(4,20,-5,LEAVES)
Block(4,20,-4,LEAVES)
Block(4,20,0,LEAVES)
Block(4,20,1,LEAVES)
Block(4,20,2,LEAVES)
Block(4,20,3,LEAVES)
Block(4,20,4,LEAVES)
Block(4,21,-5,LEAVES)
Block(4,21,1,LEAVES)
Block(4,21,2,LEAVES)
Block(4,21,3,LEAVES)
Block(4,22,2,LEAVES)
Block(5,12,4,LEAVES)
Block(5,12,5,LEAVES)
Block(5,12,6,LEAVES)
Block(5,13,2,LOG:4)
Block(5,13,3,LOG:4)
Block(5,13,4,LEAVES)
Block(5,13,5,LEAVES)
Block(5,13,6,LEAVES)
Block(5,13,7,LEAVES)
Block(5,14,4,LEAVES)
Block(5,14,5,LEAVES)
Block(5,14,6,LEAVES)
Block(5,14,7,LEAVES)
Block(5,15,-1,LEAVES)
Block(5,15,0,LOG:4)
Block(5,15,4,LEAVES)
Block(5,15,5,LEAVES)
Block(5,15,6,LEAVES)
Block(5,16,-2,LEAVES)
Block(5,16,-1,LEAVES)
Block(5,16,0,LEAVES)
Block(5,17,-7,LEAVES)
Block(5,17,-5,LEAVES)
Block(5,17,-4,LEAVES)
Block(5,17,-3,LEAVES)
Block(5,17,-1,LEAVES)
Block(5,18,-7,LEAVES)
Block(5,18,-6,LEAVES)
Block(5,18,-5,LEAVES)
Block(5,18,-4,LEAVES)
Block(5,18,-3,LEAVES)
Block(5,19,-6,LEAVES)
Block(5,19,-5,LEAVES)
Block(5,19,-4,LEAVES)
Block(5,19,0,LEAVES)
Block(5,19,1,LEAVES)
Block(5,19,2,LEAVES)
Block(5,19,3,LEAVES)
Block(5,19,4,LEAVES)
Block(5,20,-5,LEAVES)
Block(5,20,0,LEAVES)
Block(5,20,1,LEAVES)
Block(5,20,2,LOG)
Block(5,20,3,LEAVES)
Block(5,20,4,LEAVES)
Block(5,21,0,LEAVES)
Block(5,21,1,LEAVES)
Block(5,21,2,LEAVES)
Block(5,21,3,LEAVES)
Block(5,21,4,LEAVES)
Block(5,22,1,LEAVES)
Block(5,22,2,LEAVES)
Block(5,22,3,LEAVES)
Block(6,12,4,LEAVES)
Block(6,12,5,LEAVES)
Block(6,12,6,LEAVES)
Block(6,13,3,LOG:4)
Block(6,13,4,LEAVES)
Block(6,13,5,LEAVES)
Block(6,13,6,LEAVES)
Block(6,13,7,LEAVES)
Block(6,14,4,LEAVES)
Block(6,14,5,LEAVES)
Block(6,14,6,LEAVES)
Block(6,14,7,LEAVES)
Block(6,15,-3,LEAVES)
Block(6,15,-2,LEAVES)
Block(6,15,-1,LEAVES)
Block(6,15,0,LOG:4)
Block(6,15,1,LEAVES)
Block(6,15,3,LEAVES)
Block(6,15,4,LEAVES)
Block(6,15,5,LEAVES)
Block(6,15,6,LEAVES)
Block(6,16,-3,LEAVES)
Block(6,16,-2,LEAVES)
Block(6,16,-1,LEAVES)
Block(6,16,0,LEAVES)
Block(6,16,1,LEAVES)
Block(6,17,-5,LEAVES)
Block(6,17,-3,LEAVES)
Block(6,17,-2,LEAVES)
Block(6,17,-1,LEAVES)
Block(6,17,0,LEAVES)
Block(6,17,1,LEAVES)
Block(6,18,-6,LEAVES)
Block(6,18,-5,LEAVES)
Block(6,18,-4,LEAVES)
Block(6,18,-2,LEAVES)
Block(6,18,-1,LEAVES)
Block(6,18,0,LEAVES)
Block(6,19,-5,LEAVES)
Block(6,19,1,LEAVES)
Block(6,19,2,LEAVES)
Block(6,19,3,LEAVES)
Block(6,20,0,LEAVES)
Block(6,20,1,LEAVES)
Block(6,20,2,LEAVES)
Block(6,20,3,LEAVES)
Block(6,20,4,LEAVES)
Block(6,21,1,LEAVES)
Block(6,21,2,LEAVES)
Block(6,21,3,LEAVES)
Block(6,22,2,LEAVES)
Block(7,12,3,LEAVES)
Block(7,12,4,LEAVES)
Block(7,12,5,LEAVES)
Block(7,13,3,LEAVES)
Block(7,13,4,LEAVES)
Block(7,13,5,LEAVES)
Block(7,13,6,LEAVES)
Block(7,14,3,LEAVES)
Block(7,14,4,LEAVES)
Block(7,14,5,LEAVES)
Block(7,14,6,LEAVES)
Block(7,15,-3,LEAVES)
Block(7,15,-1,LEAVES)
Block(7,15,0,LEAVES)
Block(7,15,3,LEAVES)
Block(7,15,4,LEAVES)
Block(7,15,5,LEAVES)
Block(7,16,-4,LEAVES)
Block(7,16,-3,LEAVES)
Block(7,16,-2,LEAVES)
Block(7,16,-1,LOG)
Block(7,16,0,LEAVES)
Block(7,16,1,LEAVES)
Block(7,16,2,LEAVES)
Block(7,17,-3,LEAVES)
Block(7,17,-2,LEAVES)
Block(7,17,-1,LEAVES)
Block(7,17,0,LEAVES)
Block(7,17,1,LEAVES)
Block(7,18,-3,LEAVES)
Block(7,18,-2,LEAVES)
Block(7,18,-1,LEAVES)
Block(7,18,0,LEAVES)
Block(7,18,1,LEAVES)
Block(7,19,-1,LEAVES)
Block(7,19,2,LEAVES)
Block(7,20,1,LEAVES)
Block(7,20,2,LEAVES)
Block(7,20,3,LEAVES)
Block(7,21,2,LEAVES)
Block(8,12,4,LEAVES)
Block(8,13,3,LEAVES)
Block(8,13,4,LEAVES)
Block(8,13,5,LEAVES)
Block(8,14,4,LEAVES)
Block(8,14,5,LEAVES)
Block(8,15,-4,LEAVES)
Block(8,15,-3,LEAVES)
Block(8,15,-2,LEAVES)
Block(8,15,-1,LEAVES)
Block(8,15,0,LEAVES)
Block(8,15,1,LEAVES)
Block(8,15,2,LEAVES)
Block(8,15,4,LEAVES)
Block(8,16,-4,LEAVES)
Block(8,16,-3,LEAVES)
Block(8,16,-2,LEAVES)
Block(8,16,-1,LOG)
Block(8,16,0,LEAVES)
Block(8,16,1,LEAVES)
Block(8,16,2,LEAVES)
Block(8,17,-4,LEAVES)
Block(8,17,-3,LEAVES)
Block(8,17,-2,LEAVES)
Block(8,17,-1,LEAVES)
Block(8,17,0,LEAVES)
Block(8,17,1,LEAVES)
Block(8,17,2,LEAVES)
Block(8,18,-3,LEAVES)
Block(8,18,-2,LEAVES)
Block(8,18,-1,LEAVES)
Block(8,18,0,LEAVES)
Block(8,18,1,LEAVES)
Block(8,19,-2,LEAVES)
Block(8,19,-1,LEAVES)
Block(8,19,0,LEAVES)
Block(9,14,4,LEAVES)
Block(9,15,-2,LEAVES)
Block(9,15,-1,LEAVES)
Block(9,15,0,LEAVES)
Block(9,15,1,LEAVES)
Block(9,16,-4,LEAVES)
Block(9,16,-3,LEAVES)
Block(9,16,-2,LEAVES)
Block(9,16,-1,LEAVES)
Block(9,16,0,LEAVES)
Block(9,16,1,LEAVES)
Block(9,16,2,LEAVES)
Block(9,17,-3,LEAVES)
Block(9,17,-2,LEAVES)
Block(9,17,-1,LEAVES)
Block(9,17,0,LEAVES)
Block(9,17,1,LEAVES)
Block(9,18,-2,LEAVES)
Block(9,18,-1,LEAVES)
Block(9,18,0,LEAVES)
Block(9,19,-1,LEAVES)
Block(10,15,-2,LEAVES)
Block(10,15,-1,LEAVES)
Block(10,15,0,LEAVES)
Block(10,16,-3,LEAVES)
Block(10,16,-2,LEAVES)
Block(10,16,-1,LEAVES)
Block(10,16,0,LEAVES)
Block(10,16,1,LEAVES)
Block(10,17,-2,LEAVES)
Block(10,17,-1,LEAVES)
Block(10,17,0,LEAVES)
Block(10,18,-1,LEAVES)
Block(11,15,-1,LEAVES)
Block(11,16,-2,LEAVES)
Block(11,16,-1,LEAVES)
Block(11,16,0,LEAVES)
Block(11,17,-1,LEAVES)

#######################################################################
# +-----------------------------------------------------------------+ #
# |                            BO3 checks                           | #
# +-----------------------------------------------------------------+ #
#######################################################################

BlockCheck(0,-1,0,GRASS,DIRT,biomesoplenty:grass:0,biomesoplenty:grass:1,biomesoplenty:grass,biomesoplenty:grass:3,biomesoplenty:grass:4,biomesoplenty:grass:5,biomesoplenty:grass:6,biomesoplenty:grass:7,UNKNOWN_BLOCK:0,UNKNOWN_BLOCK:1,UNKNOWN_BLOCK:2,UNKNOWN_BLOCK:8,UNKNOWN_BLOCK:9,UNKNOWN_BLOCK:10,biomesoplenty:dried_sand,biomesoplenty:hard_ice,biomesoplenty:white_sand,biomesoplenty:white_sandstone,biomesoplenty:mud,biomesoplenty:ash_block)

#######################################################################
# +-----------------------------------------------------------------+ #
# |                             Branches                            | #
# +-----------------------------------------------------------------+ #
#######################################################################


#######################################################################
# +-----------------------------------------------------------------+ #
# |                             Entities                            | #
# +-----------------------------------------------------------------+ #
#######################################################################


#######################################################################
# +-----------------------------------------------------------------+ #
# |                            Particles                            | #
# +-----------------------------------------------------------------+ #
#######################################################################


#######################################################################
# +-----------------------------------------------------------------+ #
# |                             Spawners                            | #
# +-----------------------------------------------------------------+ #
#######################################################################


#######################################################################
# +-----------------------------------------------------------------+ #
# |                             ModData                             | #
# +-----------------------------------------------------------------+ #
#######################################################################

