
#######################################################################
# +-----------------------------------------------------------------+ #
# |                            BO3 object                           | #
# +-----------------------------------------------------------------+ #
#######################################################################

Author: LordSmellyPants

Description: No description given

Version: 3

SettingsMode: WriteWithoutComments


#######################################################################
# +-----------------------------------------------------------------+ #
# |                          Main settings                          | #
# +-----------------------------------------------------------------+ #
#######################################################################

Tree: true

Frequency: 1

Rarity: 10.0

RotateRandomly: true

SpawnHeight: highestSolidBlock

SpawnHeightOffset: 0

SpawnHeightVariance: 0

##############################
# Height Limits for the BO3. #
##############################

MinHeight: 62

MaxHeight: 255

######################
# Extrusion settings #
######################

ExtrudeMode: None

ExtrudeThroughBlocks: AIR

MaxBranchDepth: 10

ExcludedBiomes: All


#######################################################################
# +-----------------------------------------------------------------+ #
# |                      Source block settings                      | #
# +-----------------------------------------------------------------+ #
#######################################################################

SourceBlocks: STONE:1,STONE:3,STONE:5,DIRT:1,DIRT,SAND,GRASS,DIRT:2,STATIONARY_WATER,HARD_CLAY,STAINED_CLAY,CLAY,SANDSTONE,SAND:1,AIR,STONE,GRAVEL,LONG_GRASS,LONG_GRASS:1,LONG_GRASS:2,DEAD_BUSH,YELLOW_FLOWER,RED_ROSE,BROWN_MUSHROOM,RED_MUSHROOM,biomesoplenty:plant_0:1,biomesoplenty:plant_0:2,biomesoplenty:plant_0:3,biomesoplenty:plant_0:4,biomesoplenty:plant_0:5,biomesoplenty:plant_0:6,biomesoplenty:plant_0:7,biomesoplenty:plant_0:8,biomesoplenty:plant_0:9,biomesoplenty:plant_0:10,biomesoplenty:plant_0:11,biomesoplenty:plant_0:12,biomesoplenty:plant_0:13,biomesoplenty:plant_0:14,biomesoplenty:flower_0:1,biomesoplenty:flower_0:2,biomesoplenty:flower_0:3,biomesoplenty:flower_0:4,biomesoplenty:flower_0:5,biomesoplenty:flower_0:6,biomesoplenty:flower_0:7,biomesoplenty:flower_0:8,biomesoplenty:flower_0:9,biomesoplenty:flower_0:10,biomesoplenty:flower_0:11,biomesoplenty:flower_0:12,biomesoplenty:flower_0:13,biomesoplenty:flower_0:14,biomesoplenty:plant_1,biomesoplenty:grass:0,biomesoplenty:grass:1,biomesoplenty:grass,biomesoplenty:grass:3,biomesoplenty:grass:4,biomesoplenty:grass:5,biomesoplenty:grass:6,biomesoplenty:grass:7,UNKNOWN_BLOCK:0,UNKNOWN_BLOCK:1,UNKNOWN_BLOCK:2,UNKNOWN_BLOCK:8,UNKNOWN_BLOCK:9,UNKNOWN_BLOCK:10,biomesoplenty:dried_sand,biomesoplenty:hard_ice,biomesoplenty:white_sand,biomesoplenty:white_sandstone,biomesoplenty:mud,biomesoplenty:ash_block

MaxPercentageOutsideSourceBlock: 0

OutsideSourceBlock: placeAnyway

DoReplaceBlocks: true

IsOTGPlus: false


#######################################################################
# +-----------------------------------------------------------------+ #
# |                              Blocks                             | #
# +-----------------------------------------------------------------+ #
#######################################################################

Block(-6,14,1,LEAVES)
Block(-6,15,0,LEAVES)
Block(-6,15,1,LEAVES)
Block(-6,15,2,LEAVES)
Block(-6,16,1,LEAVES)
Block(-5,14,0,LEAVES)
Block(-5,14,1,LOG:4)
Block(-5,14,2,LEAVES)
Block(-5,15,-1,LEAVES)
Block(-5,15,0,LEAVES)
Block(-5,15,1,LEAVES)
Block(-5,15,2,LEAVES)
Block(-5,16,0,LEAVES)
Block(-5,16,1,LEAVES)
Block(-5,16,2,LEAVES)
Block(-4,12,-5,LEAVES)
Block(-4,14,1,LOG:4)
Block(-4,15,0,LEAVES)
Block(-4,15,1,LEAVES)
Block(-4,15,2,LEAVES)
Block(-4,16,1,LEAVES)
Block(-3,11,-5,LEAVES)
Block(-3,12,-6,LEAVES)
Block(-3,12,-5,LEAVES)
Block(-3,12,-4,LEAVES)
Block(-3,12,5,LEAVES)
Block(-3,13,-5,LEAVES)
Block(-3,13,1,LOG:4)
Block(-3,13,4,LEAVES)
Block(-3,13,5,LEAVES)
Block(-3,13,6,LEAVES)
Block(-3,15,0,LEAVES)
Block(-2,11,-6,LEAVES)
Block(-2,11,-5,LOG:8)
Block(-2,11,-4,LOG:8)
Block(-2,12,-6,LEAVES)
Block(-2,12,-5,LEAVES)
Block(-2,12,-4,LEAVES)
Block(-2,12,4,LOG:8)
Block(-2,12,5,LOG:8)
Block(-2,12,6,LEAVES)
Block(-2,13,-6,LEAVES)
Block(-2,13,-5,LEAVES)
Block(-2,13,-4,LEAVES)
Block(-2,13,0,LOG:4)
Block(-2,13,3,LEAVES)
Block(-2,13,4,LEAVES)
Block(-2,13,5,LEAVES)
Block(-2,14,4,LEAVES)
Block(-2,14,5,LEAVES)
Block(-2,14,6,LEAVES)
Block(-2,17,-1,LEAVES)
Block(-2,18,-2,LEAVES)
Block(-2,18,-1,LEAVES)
Block(-2,18,0,LEAVES)
Block(-2,19,-1,LEAVES)
Block(-2,19,1,LEAVES)
Block(-2,19,2,LEAVES)
Block(-2,19,3,LEAVES)
Block(-2,20,2,LEAVES)
Block(-1,11,-5,LEAVES)
Block(-1,11,-3,LOG:8)
Block(-1,11,-2,LOG:8)
Block(-1,11,-1,LOG:8)
Block(-1,12,-6,LEAVES)
Block(-1,12,-5,LEAVES)
Block(-1,12,-4,LEAVES)
Block(-1,12,3,LOG:8)
Block(-1,12,5,LEAVES)
Block(-1,13,-5,LEAVES)
Block(-1,13,0,LOG:4)
Block(-1,13,4,LEAVES)
Block(-1,13,5,LEAVES)
Block(-1,13,6,LEAVES)
Block(-1,14,5,LEAVES)
Block(-1,16,-1,LOG:8)
Block(-1,16,1,LOG:8)
Block(-1,17,-2,LEAVES)
Block(-1,17,-1,LOG)
Block(-1,17,0,LEAVES)
Block(-1,17,2,LOG)
Block(-1,18,-2,LEAVES)
Block(-1,18,-1,LEAVES)
Block(-1,18,0,LEAVES)
Block(-1,18,1,LEAVES)
Block(-1,18,2,LOG)
Block(-1,18,3,LEAVES)
Block(-1,19,-2,LEAVES)
Block(-1,19,-1,LEAVES)
Block(-1,19,0,LEAVES)
Block(-1,19,1,LEAVES)
Block(-1,19,2,LEAVES)
Block(-1,19,3,LEAVES)
Block(-1,20,1,LEAVES)
Block(-1,20,2,LEAVES)
Block(-1,20,3,LEAVES)
Block(0,-1,0,LOG)
Block(0,0,0,LOG)
Block(0,1,0,LOG)
Block(0,2,0,LOG)
Block(0,3,0,LOG)
Block(0,4,0,LOG)
Block(0,5,0,LOG)
Block(0,6,0,LOG)
Block(0,7,0,LOG)
Block(0,8,0,LOG)
Block(0,9,0,LOG)
Block(0,10,0,LOG)
Block(0,11,0,LOG)
Block(0,12,-5,LEAVES)
Block(0,12,0,LOG)
Block(0,12,1,LOG:8)
Block(0,12,2,LOG:8)
Block(0,13,0,LOG)
Block(0,14,0,LOG)
Block(0,15,0,LOG)
Block(0,16,0,LOG)
Block(0,17,-1,LEAVES)
Block(0,18,-2,LEAVES)
Block(0,18,-1,LEAVES)
Block(0,18,0,LEAVES)
Block(0,18,2,LEAVES)
Block(0,19,-1,LEAVES)
Block(0,19,1,LEAVES)
Block(0,19,2,LEAVES)
Block(0,20,2,LEAVES)
Block(1,11,0,LOG:4)
Block(1,13,-1,LOG:8)
Block(1,13,1,LOG:8)
Block(1,14,-4,LEAVES)
Block(1,14,-2,LOG:8)
Block(1,15,-5,LEAVES)
Block(1,15,-4,LEAVES)
Block(1,15,-3,LEAVES)
Block(1,15,1,LOG:4)
Block(1,16,-4,LEAVES)
Block(1,17,2,LEAVES)
Block(1,18,1,LEAVES)
Block(1,18,2,LEAVES)
Block(1,18,3,LEAVES)
Block(1,19,2,LEAVES)
Block(2,11,0,LOG:4)
Block(2,13,2,LOG:4)
Block(2,14,-5,LEAVES)
Block(2,14,-4,LOG:8)
Block(2,14,-3,LOG:8)
Block(2,15,-5,LEAVES)
Block(2,15,-4,LEAVES)
Block(2,15,-3,LEAVES)
Block(2,15,-2,LEAVES)
Block(2,16,-5,LEAVES)
Block(2,16,-4,LEAVES)
Block(2,16,-3,LEAVES)
Block(2,16,2,LOG)
Block(2,17,1,LEAVES)
Block(2,17,2,LOG)
Block(2,17,3,LEAVES)
Block(2,18,1,LEAVES)
Block(2,18,2,LEAVES)
Block(2,18,3,LEAVES)
Block(2,19,1,LEAVES)
Block(2,19,2,LEAVES)
Block(2,19,3,LEAVES)
Block(3,11,-1,LOG:4)
Block(3,13,2,LOG:4)
Block(3,14,-4,LEAVES)
Block(3,15,-5,LEAVES)
Block(3,15,-4,LEAVES)
Block(3,15,-3,LEAVES)
Block(3,15,-2,LEAVES)
Block(3,16,-4,LEAVES)
Block(3,17,2,LEAVES)
Block(3,18,0,LEAVES)
Block(3,18,1,LEAVES)
Block(3,18,2,LEAVES)
Block(3,18,3,LEAVES)
Block(3,19,2,LEAVES)
Block(4,11,-1,LOG:4)
Block(4,12,-3,LEAVES)
Block(4,12,-2,LEAVES)
Block(4,12,-1,LEAVES)
Block(4,12,0,LEAVES)
Block(4,13,-1,LEAVES)
Block(4,13,3,LOG:4)
Block(4,14,2,LEAVES)
Block(4,14,3,LEAVES)
Block(4,14,4,LEAVES)
Block(4,14,5,LEAVES)
Block(4,15,3,LEAVES)
Block(5,11,-2,LEAVES)
Block(5,11,-1,LOG:4)
Block(5,11,0,LEAVES)
Block(5,12,-2,LEAVES)
Block(5,12,-1,LEAVES)
Block(5,12,0,LEAVES)
Block(5,13,-2,LEAVES)
Block(5,13,-1,LEAVES)
Block(5,13,0,LEAVES)
Block(5,13,2,LEAVES)
Block(5,13,3,LOG:4)
Block(5,13,4,LEAVES)
Block(5,14,1,LEAVES)
Block(5,14,2,LEAVES)
Block(5,14,3,LEAVES)
Block(5,14,4,LEAVES)
Block(5,15,2,LEAVES)
Block(5,15,3,LEAVES)
Block(5,15,4,LEAVES)
Block(6,11,-1,LEAVES)
Block(6,12,-2,LEAVES)
Block(6,12,-1,LEAVES)
Block(6,12,0,LEAVES)
Block(6,13,-1,LEAVES)
Block(6,13,3,LEAVES)
Block(6,14,2,LEAVES)
Block(6,14,3,LEAVES)
Block(6,14,4,LEAVES)
Block(6,15,3,LEAVES)

#######################################################################
# +-----------------------------------------------------------------+ #
# |                            BO3 checks                           | #
# +-----------------------------------------------------------------+ #
#######################################################################

BlockCheck(0,-1,0,GRASS,DIRT,biomesoplenty:grass:0,biomesoplenty:grass:1,biomesoplenty:grass,biomesoplenty:grass:3,biomesoplenty:grass:4,biomesoplenty:grass:5,biomesoplenty:grass:6,biomesoplenty:grass:7,UNKNOWN_BLOCK:0,UNKNOWN_BLOCK:1,UNKNOWN_BLOCK:2,UNKNOWN_BLOCK:8,UNKNOWN_BLOCK:9,UNKNOWN_BLOCK:10,biomesoplenty:dried_sand,biomesoplenty:hard_ice,biomesoplenty:white_sand,biomesoplenty:white_sandstone,biomesoplenty:mud,biomesoplenty:ash_block)

#######################################################################
# +-----------------------------------------------------------------+ #
# |                             Branches                            | #
# +-----------------------------------------------------------------+ #
#######################################################################


#######################################################################
# +-----------------------------------------------------------------+ #
# |                             Entities                            | #
# +-----------------------------------------------------------------+ #
#######################################################################


#######################################################################
# +-----------------------------------------------------------------+ #
# |                            Particles                            | #
# +-----------------------------------------------------------------+ #
#######################################################################


#######################################################################
# +-----------------------------------------------------------------+ #
# |                             Spawners                            | #
# +-----------------------------------------------------------------+ #
#######################################################################


#######################################################################
# +-----------------------------------------------------------------+ #
# |                             ModData                             | #
# +-----------------------------------------------------------------+ #
#######################################################################

